<?xml version="1.0"?>
<robot xmlns:xacro="http://www.ros.org/wiki/xacro">

  <!-- Import all Gazebo-customization elements, including Gazebo colors -->
  <xacro:include filename="$(find rll_description)/urdf/iiwa7/iiwa.gazebo.xacro" />
  <!-- Import Transmissions -->
  <xacro:include filename="$(find rll_description)/urdf/iiwa7/iiwa.transmission.xacro" />

  <!-- some constants -->
  <xacro:property name="safety_controller_k_pos" value="100" />
  <xacro:property name="safety_controller_k_vel" value="2" />
  <xacro:property name="joint_damping" value="0.5" />
  <xacro:property name="max_effort" value="300"/>
  <xacro:property name="max_velocity" value="10"/>

  <xacro:macro name="iiwa7" params="parent hardware_interface robot_name *origin">

    <!--joint between {parent} and link_0-->
    <joint name="${parent}_${robot_name}_joint" type="fixed">
      <xacro:insert_block name="origin"/>
      <parent link="${parent}"/>
      <child link="${robot_name}_link_0"/>
    </joint>

    <link name="${robot_name}_link_0">
      <inertial>
        <origin xyz="-0.1 0 0.07" rpy="0 0 0"/>
        <mass value="5"/>
        <inertia ixx="0.05"  ixy="0"  ixz="0" iyy="0.06" iyz="0" izz="0.03" />
      </inertial>

      <visual>
        <geometry>
          <mesh filename="package://rll_description/meshes/iiwa7/visual/base.dae"/>
        </geometry>
      </visual>

      <collision>
        <geometry>
          <mesh filename="package://rll_description/meshes/iiwa7/collision/base.stl"/>
        </geometry>
      </collision>

      <self_collision_checking>
        <origin xyz="0 0 0" rpy="0 0 0"/>
        <geometry>
          <capsule radius="0.15" length="0.25"/>
        </geometry>
      </self_collision_checking>

    </link>

    <!-- joint between link_0 and link_1 -->
    <joint name="${robot_name}_joint_1" type="revolute">
      <parent link="${robot_name}_link_0"/>
      <child link="${robot_name}_link_1"/>
      <origin xyz="0 0 0.157" rpy="0 0 0"/>
      <axis xyz="0 0 1"/>
      <limit lower="${-170 * pi / 180}" upper="${170 * pi / 180}"
             effort="${max_effort}" velocity="${98 * pi / 180}" />
      <safety_controller soft_lower_limit="${-168 * pi / 180}"
                         soft_upper_limit="${168 * pi / 180}"
                         k_position="${safety_controller_k_pos}"
                         k_velocity="${safety_controller_k_vel}"/>
      <dynamics damping="${joint_damping}"/>
    </joint>

    <link name="${robot_name}_link_1">
      <inertial>
        <origin xyz="0 -0.03 0.12" rpy="0 0 0"/>
        <mass value="3.4525"/>
        <inertia ixx="0.02183"  ixy="0"  ixz="0" iyy="0.007703" iyz="-0.003887" izz="0.02083" />
      </inertial>
      <visual>
        <geometry>
          <mesh filename="package://rll_description/meshes/iiwa7/visual/link1.dae"/>
        </geometry>
      </visual>
      <collision>
        <geometry>
          <mesh filename="package://rll_description/meshes/iiwa7/collision/link1.stl"/>
        </geometry>
      </collision>
    </link>

    <joint name="${robot_name}_joint_2" type="revolute">
      <parent link="${robot_name}_link_1"/>
      <child link="${robot_name}_link_2"/>
      <origin xyz="0 0 0.183" rpy="0 0 0"/>
      <axis xyz="0 1 0"/>
      <limit lower="${-120 * pi / 180}" upper="${120 * pi / 180}"
             effort="${max_effort}" velocity="${98 * pi / 180}" />
      <safety_controller soft_lower_limit="${-118 * pi / 180}"
                         soft_upper_limit="${118 * pi / 180}"
                         k_position="${safety_controller_k_pos}"
                         k_velocity="${safety_controller_k_vel}"/>
      <dynamics damping="${joint_damping}"/>
    </joint>

    <link name="${robot_name}_link_2">
      <inertial>
        <origin xyz="0.0003 0.059 0.042" rpy="0 0 0"/>
        <mass value="3.4821"/>
        <inertia ixx="0.02076"  ixy="0"  ixz="-0.003626" iyy="0.02179" iyz="0" izz="0.00779" />
      </inertial>
      <visual>
        <geometry>
          <mesh filename="package://rll_description/meshes/iiwa7/visual/link2.dae"/>
        </geometry>
      </visual>

      <collision>
        <geometry>
          <mesh filename="package://rll_description/meshes/iiwa7/collision/link2.stl"/>
        </geometry>
      </collision>
    </link>

    <joint name="${robot_name}_joint_3" type="revolute">
      <parent link="${robot_name}_link_2"/>
      <child link="${robot_name}_link_3"/>
      <origin xyz="0 0 0.185" rpy="0 0 0"/>
      <axis xyz="0 0 1"/>
      <limit lower="${-170 * pi / 180}" upper="${170 * pi / 180}"
             effort="${max_effort}" velocity="${100 * pi / 180}" />
      <safety_controller soft_lower_limit="${-168 * pi / 180}"
                         soft_upper_limit="${168 * pi / 180}"
                         k_position="${safety_controller_k_pos}"
                         k_velocity="${safety_controller_k_vel}"/>
      <dynamics damping="${joint_damping}"/>
    </joint>

    <link name="${robot_name}_link_3">
      <inertial>
        <origin xyz="0 0.03 0.13" rpy="0 0 0"/>
        <mass value="4.05623"/>
        <inertia ixx="0.03204"  ixy="0"  ixz="0" iyy="0.00972" iyz="0.006227" izz="0.03042" />
      </inertial>

      <visual>
        <geometry>
          <mesh filename="package://rll_description/meshes/iiwa7/visual/link3.dae"/>
        </geometry>
      </visual>

      <collision>
        <geometry>
          <mesh filename="package://rll_description/meshes/iiwa7/collision/link3.stl"/>
        </geometry>
      </collision>

    </link>

    <joint name="${robot_name}_joint_4" type="revolute">
      <parent link="${robot_name}_link_3"/>
      <child link="${robot_name}_link_4"/>
      <origin xyz="0 0 0.215" rpy="0 0 0"/>
      <axis xyz="0 -1 0"/>
      <limit lower="${-120 * pi / 180}" upper="${120 * pi / 180}"
             effort="${max_effort}" velocity="${130 * pi / 180}" />
      <safety_controller soft_lower_limit="${-118 * pi / 180}"
                         soft_upper_limit="${118 * pi / 180}"
                         k_position="${safety_controller_k_pos}"
                         k_velocity="${safety_controller_k_vel}"/>
      <dynamics damping="${joint_damping}"/>
    </joint>

    <link name="${robot_name}_link_4">
      <inertial>
        <origin xyz="0 0.067 0.034" rpy="0 0 0"/>
        <mass value="3.4822"/>
        <inertia ixx="0.02178"  ixy="0"  ixz="0" iyy="0.02075" iyz="-0.003625" izz="0.007785" />
      </inertial>

      <visual>
        <geometry>
          <mesh filename="package://rll_description/meshes/iiwa7/visual/link4.dae"/>
        </geometry>
      </visual>

      <collision>
        <geometry>
          <mesh filename="package://rll_description/meshes/iiwa7/collision/link4.stl"/>
        </geometry>
      </collision>
    </link>

    <joint name="${robot_name}_joint_5" type="revolute">
      <parent link="${robot_name}_link_4"/>
      <child link="${robot_name}_link_5"/>
      <origin xyz="0 0 0.4" rpy="0 0 0"/>
      <axis xyz="0 0 1"/>
      <limit lower="${-170 * pi / 180}" upper="${170 * pi / 180}"
             effort="${max_effort}" velocity="${140 * pi / 180}" />
      <safety_controller soft_lower_limit="${-168 * pi / 180}"
                         soft_upper_limit="${168 * pi / 180}"
                         k_position="${safety_controller_k_pos}"
                         k_velocity="${safety_controller_k_vel}"/>
      <dynamics damping="${joint_damping}"/>
    </joint>

    <link name="${robot_name}_link_5">
      <inertial>
        <origin xyz="0.0001 0.021 0.076" rpy="0 0 0"/>
        <mass value="2.1633"/>
        <inertia ixx="0.01287"  ixy="0"  ixz="0" iyy="0.005708" iyz="-0.003946" izz="0.01112" />
      </inertial>

      <visual>
        <geometry>
          <mesh filename="package://rll_description/meshes/iiwa7/visual/link5.dae"/>
        </geometry>
      </visual>

      <collision>
        <geometry>
          <mesh filename="package://rll_description/meshes/iiwa7/collision/link5.stl"/>
        </geometry>
      </collision>
    </link>

    <joint name="${robot_name}_joint_6" type="revolute">
      <parent link="${robot_name}_link_5"/>
      <child link="${robot_name}_link_6"/>
      <origin xyz="0 0 0" rpy="0 0 0"/>
      <axis xyz="0 1 0"/>
      <limit lower="${-120 * pi / 180}" upper="${120 * pi / 180}"
             effort="${max_effort}" velocity="${180 * pi / 180}" />
      <safety_controller soft_lower_limit="${-118 * pi / 180}"
                         soft_upper_limit="${118 * pi / 180}"
                         k_position="${safety_controller_k_pos}"
                         k_velocity="${safety_controller_k_vel}"/>
      <dynamics damping="${joint_damping}"/>
    </joint>

    <link name="${robot_name}_link_6">
      <inertial>
        <origin xyz="0 0.0006 0.0004" rpy="0 0 0"/>
        <mass value="2.3466"/>
        <inertia ixx="0.006509"  ixy="0"  ixz="0" iyy="0.006259" iyz="0.00031891" izz="0.004527" />
      </inertial>

      <visual>
        <geometry>
          <mesh filename="package://rll_description/meshes/iiwa7/visual/link6.dae"/>
        </geometry>
      </visual>

      <collision>
        <geometry>
          <mesh filename="package://rll_description/meshes/iiwa7/collision/link6.stl"/>
        </geometry>
      </collision>
    </link>

    <joint name="${robot_name}_joint_7" type="revolute">
      <parent link="${robot_name}_link_6"/>
      <child link="${robot_name}_link_7"/>
      <origin xyz="0 0 0" rpy="0 0 0"/>
      <axis xyz="0 0 1"/>
      <limit lower="${-175 * pi / 180}" upper="${175 * pi / 180}"
             effort="${max_effort}" velocity="${180 * pi / 180}" />
      <safety_controller soft_lower_limit="${-173 * pi / 180}"
                         soft_upper_limit="${173 * pi / 180}"
                         k_position="${safety_controller_k_pos}"
                         k_velocity="${safety_controller_k_vel}"/>
      <dynamics damping="${joint_damping}"/>
    </joint>

    <link name="${robot_name}_link_7">
      <inertial>
        <origin xyz="0 0 0.02" rpy="0 0 0"/>
        <mass value="3.129"/>
        <inertia ixx="0.01464"  ixy="0.0005912"  ixz="0" iyy="0.01465" iyz="0" izz="0.002872" />
      </inertial>

      <visual>
        <geometry>
          <mesh filename="package://rll_description/meshes/iiwa7/visual/link7.dae"/>
        </geometry>
      </visual>

      <collision>
        <geometry>
          <mesh filename="package://rll_description/meshes/iiwa7/collision/link7.stl"/>
        </geometry>
      </collision>
    </link>

    <joint name="${robot_name}_joint_ee" type="fixed">
      <parent link="${robot_name}_link_7"/>
      <child link="${robot_name}_link_ee"/>
      <origin xyz="0 0 0.126" rpy="0 0 0"/>
    </joint>

    <link name="${robot_name}_link_ee">
    </link>

    <!--Extensions -->
    <xacro:iiwa_gazebo robot_name="${robot_name}" />
    <xacro:iiwa_transmission hardware_interface="${hardware_interface}"/>

  </xacro:macro>

</robot>
