<?xml version="1.0"?>
<robot name="egl90" xmlns:xacro="http://www.ros.org/wiki/xacro">
  <xacro:property name="finger_visual_mesh_path" value="package://rll_description/meshes/egl90/visual/gripper_finger.dae" />
  <xacro:property name="finger_collision_mesh_path" value="package://rll_description/meshes/egl90/collision/gripper_finger.stl" />
  <xacro:property name="finger_mass" value="0.1" />
  <xacro:property name="joint_lower_limit" value="0.0" />
  <xacro:property name="joint_upper_limit" value="0.055" />

  <xacro:macro name="egl90" params="parent prefix">

    <joint name="gripper_adapter_joint" type="fixed">
      <parent link="${parent}" />
      <child link="${prefix}gripper_adapter" />
      <origin xyz="0 0 0" rpy="0 0 ${-90 * pi / 180}"/>
    </joint>
    <link name="${prefix}gripper_adapter">
      <visual>
        <origin xyz="0 0 0" rpy="0 0 0"/>
        <geometry>
          <mesh filename="package://rll_description/meshes/egl90/visual/gripper_adapter.dae" />
        </geometry>
      </visual>
      <collision>
        <origin xyz="0 0 0.015" rpy="0 0 0"/>
        <geometry>
          <box size="0.09 0.07 0.03"/>
        </geometry>
      </collision>
    </link>

    <joint name="${prefix}gripper_mount" type="fixed">
      <parent link="${prefix}gripper_adapter"/>
      <child link="${prefix}gripper_base"/>
      <origin xyz="0 0 0.024" rpy="0 0 0"/>
    </joint>
    <link name="${prefix}gripper_base">
      <inertial>
        <origin xyz="0 0 0" rpy="0 0 0"/>
        <mass value="0.3"/>
        <inertia ixx="0.0001" ixy="0" ixz="0" iyy="0.0002" iyz="0" izz="0.0001"/>
      </inertial>
      <visual>
        <origin xyz="0 0 0" rpy="0 0 0" />
        <geometry>
          <mesh filename="package://rll_description/meshes/egl90/visual/gripper_base.dae" />
        </geometry>
      </visual>
      <collision>
        <origin xyz="-0.025 0 0.055" rpy="0 0 0"/>
        <geometry>
          <box size="0.18 0.09 0.108"/>
        </geometry>
      </collision>
    </link>

    <joint name="${prefix}egl_position_left" type="prismatic">
      <parent link="${prefix}gripper_base"/>
      <child link="${prefix}gripper_waggon_left"/>
      <origin xyz="0.02985 0.0255 0.1063" rpy="0 0 ${180 * pi / 180}"/>
      <axis xyz="1 0 0"/>
      <limit effort="1000.0" lower="${joint_lower_limit}" upper="${joint_upper_limit}" velocity="100.0"/>
    </joint>
    <link name="${prefix}gripper_waggon_left">
      <visual>
        <origin xyz="0 0 0" rpy="0 0 0"/>
        <geometry>
          <mesh filename="package://rll_description/meshes/egl90/visual/gripper_waggon.dae" />
        </geometry>
      </visual>
      <collision>
        <origin xyz="0 0 -0.01" rpy="0 0 0"/>
        <geometry>
          <box size="0.06 0.035 0.02"/>
        </geometry>
      </collision>
    </link>

    <joint name="${prefix}gripper_finger_left_joint" type="fixed">
      <parent link="${prefix}gripper_waggon_left"/>
      <child link="${prefix}gripper_finger_left"/>
      <origin xyz="-0.016 0 0" rpy="0 0 0"/>
    </joint>
    <link name="${prefix}gripper_finger_left">
      <inertial>
        <origin xyz="0 0 0" rpy="0 0 0"/>
        <mass value="${finger_mass}"/>
        <inertia ixx="0.002" ixy="0" ixz="0" iyy="0.0002" iyz="0" izz="0.0002"/>
      </inertial>
      <visual>
        <origin xyz="0 0 0" rpy="0 0 0"/>
        <geometry>
          <mesh filename="${finger_visual_mesh_path}" />
        </geometry>
      </visual>
      <collision>
        <origin xyz="0 0 0" rpy="0 0 0"/>
        <geometry>
          <mesh filename="${finger_collision_mesh_path}" />
        </geometry>
      </collision>
    </link>

    <joint name="${prefix}egl_position_right" type="prismatic">
      <parent link="${prefix}gripper_base"/>
      <child link="${prefix}gripper_waggon_right"/>
      <origin xyz="-0.02985 -0.0255 0.1063" rpy="0 0 0"/>
      <axis xyz="1 0 0"/>
      <limit effort="1000.0" lower="${joint_lower_limit}" upper="${joint_upper_limit}" velocity="100.0"/>
    </joint>
    <link name="${prefix}gripper_waggon_right">
      <visual>
        <origin xyz="0 0 0" rpy="0 0 0"/>
        <geometry>
          <mesh filename="package://rll_description/meshes/egl90/visual/gripper_waggon.dae" />
        </geometry>
      </visual>
      <collision>
        <origin xyz="0 0 -0.01" rpy="0 0 0"/>
        <geometry>
          <box size="0.06 0.035 0.02"/>
        </geometry>
      </collision>
    </link>

    <joint name="${prefix}gripper_finger_right_joint" type="fixed">
      <parent link="${prefix}gripper_waggon_right"/>
      <child link="${prefix}gripper_finger_right"/>
      <origin xyz="-0.016 0 0" rpy="0 0 0"/>
    </joint>
    <link name="${prefix}gripper_finger_right">
      <inertial>
        <origin xyz="0 0 0" rpy="0 0 0"/>
        <mass value="${finger_mass}"/>
        <inertia ixx="0.002" ixy="0" ixz="0" iyy="0.0002" iyz="0" izz="0.0002"/>
      </inertial>
      <visual>
        <origin xyz="0 0 0" rpy="0 0 0"/>
        <geometry>
          <mesh filename="${finger_visual_mesh_path}" />
        </geometry>
      </visual>
      <collision>
        <origin xyz="0 0 0" rpy="0 0 0"/>
        <geometry>
          <mesh filename="${finger_collision_mesh_path}" />
        </geometry>
      </collision>
    </link>

  </xacro:macro>

</robot>
